2019-03-24 23:47:03,601 - instagram_scraper.app - DEBUG - Exception in worker thread
Traceback (most recent call last):
  File "/usr/local/lib/python3.7/site-packages/instagram_scraper/app.py", line 385, in worker_wrapper
    return fn(*args, **kwargs)
  File "/usr/local/lib/python3.7/site-packages/instagram_scraper/app.py", line 956, in download
    os.rename(part_file, file_path)
FileNotFoundError: [Errno 2] No such file or directory: '/Users/user/Downloads/insta_meta_test2/54247826_406492543498413_4408451725323963880_n.jpg.part' -> '/Users/user/Downloads/insta_meta_test2/54247826_406492543498413_4408451725323963880_n.jpg'
2019-03-24 23:47:03,604 - instagram_scraper.app - WARNING - Media for 1000일 at ['https://scontent-hkg3-2.cdninstagram.com/vp/2703eafd05f326917b7e4c8a46b1a6f4/5D4DA614/t51.2885-15/e35/54247826_406492543498413_4408451725323963880_n.jpg?_nc_ht=scontent-hkg3-2.cdninstagram.com', 'https://scontent-hkg3-2.cdninstagram.com/vp/4e6d1177d00a6df210606d1a57fb79a5/5D4BA89F/t51.2885-15/e35/54247976_307246989973529_6850279658178313111_n.jpg?_nc_ht=scontent-hkg3-2.cdninstagram.com', 'https://scontent-hkg3-2.cdninstagram.com/vp/69510d4e17a112218d0a199fccce940d/5D1AB15F/t51.2885-15/e35/53483020_279174293002519_5357974236796245421_n.jpg?_nc_ht=scontent-hkg3-2.cdninstagram.com', 'https://scontent-hkg3-2.cdninstagram.com/vp/551781e90ffb22cc0a1a42e661566749/5D48AABD/t51.2885-15/e35/52421041_151153005913409_5905253131549301822_n.jpg?_nc_ht=scontent-hkg3-2.cdninstagram.com'] generated an exception: [Errno 2] No such file or directory: '/Users/user/Downloads/insta_meta_test2/54247826_406492543498413_4408451725323963880_n.jpg.part' -> '/Users/user/Downloads/insta_meta_test2/54247826_406492543498413_4408451725323963880_n.jpg'
2019-03-24 23:47:03,800 - instagram_scraper.app - DEBUG - Exception in worker thread
Traceback (most recent call last):
  File "/usr/local/lib/python3.7/site-packages/instagram_scraper/app.py", line 385, in worker_wrapper
    return fn(*args, **kwargs)
  File "/usr/local/lib/python3.7/site-packages/instagram_scraper/app.py", line 956, in download
    os.rename(part_file, file_path)
FileNotFoundError: [Errno 2] No such file or directory: '/Users/user/Downloads/insta_meta_test2/53328193_125939888498545_4455958523315115897_n.jpg.part' -> '/Users/user/Downloads/insta_meta_test2/53328193_125939888498545_4455958523315115897_n.jpg'
2019-03-24 23:47:03,800 - instagram_scraper.app - WARNING - Media for 1000일 at ['https://scontent-hkg3-2.cdninstagram.com/vp/684be93b04631f2272278ebfb646db41/5D1830FB/t51.2885-15/e35/53328193_125939888498545_4455958523315115897_n.jpg?_nc_ht=scontent-hkg3-2.cdninstagram.com', 'https://scontent-hkg3-2.cdninstagram.com/vp/c6f102f035049578eb73dddd51e5f30b/5D1B7136/t51.2885-15/e35/53892638_368888727288123_4560904988786816747_n.jpg?_nc_ht=scontent-hkg3-2.cdninstagram.com', 'https://scontent-hkg3-2.cdninstagram.com/vp/2dd28e72ce400772fd49b395abdc3371/5D2E2B2D/t51.2885-15/e35/53693004_632197003884227_3331202299305372388_n.jpg?_nc_ht=scontent-hkg3-2.cdninstagram.com', 'https://scontent-hkg3-2.cdninstagram.com/vp/a9a316fc430559281abbc28f91b7e713/5D4AE455/t51.2885-15/e35/53742708_799444190429367_4994666625774453750_n.jpg?_nc_ht=scontent-hkg3-2.cdninstagram.com', 'https://scontent-hkg3-2.cdninstagram.com/vp/2d3c9bf2ea05ceb8df6e2a000a33906d/5D143546/t51.2885-15/e35/52849622_233817567575502_640003139690526416_n.jpg?_nc_ht=scontent-hkg3-2.cdninstagram.com', 'https://scontent-hkg3-2.cdninstagram.com/vp/9b0e936b3b957c3e136a48826bc55465/5D32869D/t51.2885-15/e35/54512831_532954043897886_5579777336347916304_n.jpg?_nc_ht=scontent-hkg3-2.cdninstagram.com'] generated an exception: [Errno 2] No such file or directory: '/Users/user/Downloads/insta_meta_test2/53328193_125939888498545_4455958523315115897_n.jpg.part' -> '/Users/user/Downloads/insta_meta_test2/53328193_125939888498545_4455958523315115897_n.jpg'
2019-03-24 23:47:04,160 - instagram_scraper.app - DEBUG - Exception in worker thread
Traceback (most recent call last):
  File "/usr/local/lib/python3.7/site-packages/instagram_scraper/app.py", line 385, in worker_wrapper
    return fn(*args, **kwargs)
  File "/usr/local/lib/python3.7/site-packages/instagram_scraper/app.py", line 956, in download
    os.rename(part_file, file_path)
FileNotFoundError: [Errno 2] No such file or directory: '/Users/user/Downloads/insta_meta_test2/53515514_566949107118763_7263284083892782128_n.jpg.part' -> '/Users/user/Downloads/insta_meta_test2/53515514_566949107118763_7263284083892782128_n.jpg'
2019-03-24 23:47:04,161 - instagram_scraper.app - WARNING - Media for 1000일 at ['https://scontent-hkg3-2.cdninstagram.com/vp/a0f0f812c200f6a23591d3b3b2bbfeea/5D100851/t51.2885-15/e35/53515514_566949107118763_7263284083892782128_n.jpg?_nc_ht=scontent-hkg3-2.cdninstagram.com'] generated an exception: [Errno 2] No such file or directory: '/Users/user/Downloads/insta_meta_test2/53515514_566949107118763_7263284083892782128_n.jpg.part' -> '/Users/user/Downloads/insta_meta_test2/53515514_566949107118763_7263284083892782128_n.jpg'
2019-03-24 23:47:04,441 - instagram_scraper.app - DEBUG - Exception in worker thread
Traceback (most recent call last):
  File "/usr/local/lib/python3.7/site-packages/instagram_scraper/app.py", line 385, in worker_wrapper
    return fn(*args, **kwargs)
  File "/usr/local/lib/python3.7/site-packages/instagram_scraper/app.py", line 956, in download
    os.rename(part_file, file_path)
FileNotFoundError: [Errno 2] No such file or directory: '/Users/user/Downloads/insta_meta_test2/54513163_2002964376679663_1294277343820349804_n.jpg.part' -> '/Users/user/Downloads/insta_meta_test2/54513163_2002964376679663_1294277343820349804_n.jpg'
2019-03-24 23:47:04,441 - instagram_scraper.app - WARNING - Media for 1000일 at ['https://scontent-hkg3-2.cdninstagram.com/vp/26d98da538408f9b0143afd25a9aeb21/5D4FAE41/t51.2885-15/e35/54513163_2002964376679663_1294277343820349804_n.jpg?_nc_ht=scontent-hkg3-2.cdninstagram.com', 'https://scontent-hkg3-2.cdninstagram.com/vp/7dff1a0dbf29ddc318a5b6d18a703fd0/5D4D52B6/t51.2885-15/e35/53556217_434183307353486_2463661842955337824_n.jpg?_nc_ht=scontent-hkg3-2.cdninstagram.com', 'https://scontent-hkg3-2.cdninstagram.com/vp/8c823b65ac7de73eb5bbed3be17c17ca/5D2E0377/t51.2885-15/e35/53617186_2238183676498819_7808950935717241425_n.jpg?_nc_ht=scontent-hkg3-2.cdninstagram.com', 'https://scontent-hkg3-2.cdninstagram.com/vp/8915897d47ff727dc6e430370df66bb1/5D4A7978/t51.2885-15/e35/53712776_184243629207280_2925744088851822057_n.jpg?_nc_ht=scontent-hkg3-2.cdninstagram.com', 'https://scontent-hkg3-2.cdninstagram.com/vp/6dbe2623c7ac6536e22cb0fc31ab5c3d/5D2F2939/t51.2885-15/e35/53813372_130340471430280_106465348219606356_n.jpg?_nc_ht=scontent-hkg3-2.cdninstagram.com', 'https://scontent-hkg3-2.cdninstagram.com/vp/70b7eb698792a32e57b2501fe65c837d/5D0EB2DF/t51.2885-15/e35/52582825_190891355210639_367045324413093162_n.jpg?_nc_ht=scontent-hkg3-2.cdninstagram.com'] generated an exception: [Errno 2] No such file or directory: '/Users/user/Downloads/insta_meta_test2/54513163_2002964376679663_1294277343820349804_n.jpg.part' -> '/Users/user/Downloads/insta_meta_test2/54513163_2002964376679663_1294277343820349804_n.jpg'
2019-03-24 23:48:38,685 - instagram_scraper.app - DEBUG - Exception in worker thread
Traceback (most recent call last):
  File "/usr/local/lib/python3.7/site-packages/instagram_scraper/app.py", line 385, in worker_wrapper
    return fn(*args, **kwargs)
  File "/usr/local/lib/python3.7/site-packages/instagram_scraper/app.py", line 956, in download
    os.rename(part_file, file_path)
FileNotFoundError: [Errno 2] No such file or directory: '/Users/user/Downloads/insta_meta_test2/52355819_351898185431916_8645121128078664222_n.jpg.part' -> '/Users/user/Downloads/insta_meta_test2/52355819_351898185431916_8645121128078664222_n.jpg'
2019-03-24 23:48:38,686 - instagram_scraper.app - WARNING - Media for 2000일 at ['https://scontent-hkg3-2.cdninstagram.com/vp/5bfea54f9b48a444ff4c626bc6778d1c/5D1481AF/t51.2885-15/e35/52355819_351898185431916_8645121128078664222_n.jpg?_nc_ht=scontent-hkg3-2.cdninstagram.com', 'https://scontent-hkg3-2.cdninstagram.com/vp/5300b01bdd35c8548b36a14d291c7abe/5D163006/t51.2885-15/e35/52803989_316905189027701_308229145195307084_n.jpg?_nc_ht=scontent-hkg3-2.cdninstagram.com'] generated an exception: [Errno 2] No such file or directory: '/Users/user/Downloads/insta_meta_test2/52355819_351898185431916_8645121128078664222_n.jpg.part' -> '/Users/user/Downloads/insta_meta_test2/52355819_351898185431916_8645121128078664222_n.jpg'
2019-03-24 23:48:39,037 - instagram_scraper.app - DEBUG - Exception in worker thread
Traceback (most recent call last):
  File "/usr/local/lib/python3.7/site-packages/instagram_scraper/app.py", line 385, in worker_wrapper
    return fn(*args, **kwargs)
  File "/usr/local/lib/python3.7/site-packages/instagram_scraper/app.py", line 956, in download
    os.rename(part_file, file_path)
FileNotFoundError: [Errno 2] No such file or directory: '/Users/user/Downloads/insta_meta_test2/53070164_442097813200794_783302020485086721_n.jpg.part' -> '/Users/user/Downloads/insta_meta_test2/53070164_442097813200794_783302020485086721_n.jpg'
2019-03-24 23:48:39,038 - instagram_scraper.app - WARNING - Media for 2000일 at ['https://scontent-hkg3-2.cdninstagram.com/vp/bfa5dbe0591ee3b3540be26a75165cbb/5D0F0A3C/t51.2885-15/e35/53070164_442097813200794_783302020485086721_n.jpg?_nc_ht=scontent-hkg3-2.cdninstagram.com', 'https://scontent-hkg3-2.cdninstagram.com/vp/ad48ecb0c97c831f8f9508d08a0391f6/5D0F414D/t51.2885-15/e35/52847525_255984432023737_2630256234940245552_n.jpg?_nc_ht=scontent-hkg3-2.cdninstagram.com', 'https://scontent-hkg3-2.cdninstagram.com/vp/934b5540456476380131de9f83e7e546/5D4FA983/t51.2885-15/e35/54513097_2244917442388998_6177254764916451180_n.jpg?_nc_ht=scontent-hkg3-2.cdninstagram.com', 'https://scontent-hkg3-2.cdninstagram.com/vp/2f15755a9a822627e0216d5474ea3f63/5D19D7CC/t51.2885-15/e35/53014756_1910792832364323_6166430066721021390_n.jpg?_nc_ht=scontent-hkg3-2.cdninstagram.com', 'https://scontent-hkg3-2.cdninstagram.com/vp/613958c4dc97b14d4f548112b85f4991/5D329CD5/t51.2885-15/e35/53482485_360334517901835_87884951841146566_n.jpg?_nc_ht=scontent-hkg3-2.cdninstagram.com', 'https://scontent-hkg3-2.cdninstagram.com/vp/d11154d9f58542c4617a25fd92758cb2/5D114703/t51.2885-15/e35/52983374_584101315333972_7095129490481181986_n.jpg?_nc_ht=scontent-hkg3-2.cdninstagram.com', 'https://scontent-hkg3-2.cdninstagram.com/vp/ca07f215834c9a767192701611c51039/5D4B66C9/t51.2885-15/e35/53415105_146837099680179_6231261800740415070_n.jpg?_nc_ht=scontent-hkg3-2.cdninstagram.com', 'https://scontent-hkg3-2.cdninstagram.com/vp/644f42189954e81695221192b733362a/5D123B1D/t51.2885-15/e35/52764762_1017182075145954_7048032897433068895_n.jpg?_nc_ht=scontent-hkg3-2.cdninstagram.com'] generated an exception: [Errno 2] No such file or directory: '/Users/user/Downloads/insta_meta_test2/53070164_442097813200794_783302020485086721_n.jpg.part' -> '/Users/user/Downloads/insta_meta_test2/53070164_442097813200794_783302020485086721_n.jpg'
2019-03-24 23:48:40,223 - instagram_scraper.app - DEBUG - Exception in worker thread
Traceback (most recent call last):
  File "/usr/local/lib/python3.7/site-packages/instagram_scraper/app.py", line 385, in worker_wrapper
    return fn(*args, **kwargs)
  File "/usr/local/lib/python3.7/site-packages/instagram_scraper/app.py", line 956, in download
    os.rename(part_file, file_path)
FileNotFoundError: [Errno 2] No such file or directory: '/Users/user/Downloads/insta_meta_test2/52922718_821162244934658_286242834918113377_n.jpg.part' -> '/Users/user/Downloads/insta_meta_test2/52922718_821162244934658_286242834918113377_n.jpg'
2019-03-24 23:48:40,223 - instagram_scraper.app - WARNING - Media for 2000일 at ['https://scontent-hkg3-2.cdninstagram.com/vp/aad1c79837b89835504489eb2133deb4/5D2D5546/t51.2885-15/e35/52922718_821162244934658_286242834918113377_n.jpg?_nc_ht=scontent-hkg3-2.cdninstagram.com', 'https://scontent-hkg3-2.cdninstagram.com/vp/380e4ae733f7eefaa2a2d96f6bec5a27/5D481913/t51.2885-15/e35/53895438_258495871721412_7520816077467866397_n.jpg?_nc_ht=scontent-hkg3-2.cdninstagram.com', 'https://scontent-hkg3-2.cdninstagram.com/vp/3631031ff63ac5c9a7332831d8e26ab4/5D47398B/t51.2885-15/e35/53581882_2379002688801073_2527897975894633268_n.jpg?_nc_ht=scontent-hkg3-2.cdninstagram.com', 'https://scontent-hkg3-2.cdninstagram.com/vp/49692ef22e3fe130e1ecfec5d0ec5ec6/5D160727/t51.2885-15/e35/53800845_2163701383718650_3916885821264014979_n.jpg?_nc_ht=scontent-hkg3-2.cdninstagram.com'] generated an exception: [Errno 2] No such file or directory: '/Users/user/Downloads/insta_meta_test2/52922718_821162244934658_286242834918113377_n.jpg.part' -> '/Users/user/Downloads/insta_meta_test2/52922718_821162244934658_286242834918113377_n.jpg'
2019-03-24 23:48:40,855 - instagram_scraper.app - DEBUG - Exception in worker thread
Traceback (most recent call last):
  File "/usr/local/lib/python3.7/site-packages/instagram_scraper/app.py", line 385, in worker_wrapper
    return fn(*args, **kwargs)
  File "/usr/local/lib/python3.7/site-packages/instagram_scraper/app.py", line 956, in download
    os.rename(part_file, file_path)
FileNotFoundError: [Errno 2] No such file or directory: '/Users/user/Downloads/insta_meta_test2/40018615_681232688905528_3207780218613792768_n.jpg.part' -> '/Users/user/Downloads/insta_meta_test2/40018615_681232688905528_3207780218613792768_n.jpg'
2019-03-24 23:48:40,856 - instagram_scraper.app - WARNING - Media for 2000일 at ['https://scontent-hkg3-2.cdninstagram.com/vp/a5de74218dafe8f3872c00dfefd5e808/5D4B4D7F/t51.2885-15/e35/40018615_681232688905528_3207780218613792768_n.jpg?_nc_ht=scontent-hkg3-2.cdninstagram.com', 'https://scontent-hkg3-2.cdninstagram.com/vp/706df55dc1d85d25533ca96a83ad39ec/5D4A1302/t51.2885-15/e35/40640764_294612501328441_6936610158587936768_n.jpg?_nc_ht=scontent-hkg3-2.cdninstagram.com', 'https://scontent-hkg3-2.cdninstagram.com/vp/6405c14b8090a2ebba46873dc4c4c35d/5D467F53/t51.2885-15/e35/40357108_753776658347731_1184967342229028864_n.jpg?_nc_ht=scontent-hkg3-2.cdninstagram.com', 'https://scontent-hkg3-2.cdninstagram.com/vp/b636cd10aaadb58c1285421e925e5f07/5D33F3CC/t51.2885-15/e35/39352012_1843339435780929_2994138203029504000_n.jpg?_nc_ht=scontent-hkg3-2.cdninstagram.com', 'https://scontent.cdninstagram.com/vp/5f203fb4ce92d9e62fc258ed2c9e19cf/5C99C3A3/t50.2886-16/40471481_284274388847351_3463445866911780758_n.mp4?_nc_ht=scontent.cdninstagram.com', 'https://scontent-hkg3-2.cdninstagram.com/vp/0a328a6b3374ea249dce5932af9d5a68/5D34926C/t51.2885-15/e35/39936526_2234773846754967_9145461918515855360_n.jpg?_nc_ht=scontent-hkg3-2.cdninstagram.com', 'https://scontent-hkg3-2.cdninstagram.com/vp/99ce86a4b5e907b1b9cbd92bed879ec9/5D165C69/t51.2885-15/e35/40733757_498104857321983_4363288921325436928_n.jpg?_nc_ht=scontent-hkg3-2.cdninstagram.com', 'https://scontent-hkg3-2.cdninstagram.com/vp/b3ffd259140c2607157bbe37680fb0b9/5D4A0E2B/t51.2885-15/e35/39881689_684397111959268_7633813866194927616_n.jpg?_nc_ht=scontent-hkg3-2.cdninstagram.com'] generated an exception: [Errno 2] No such file or directory: '/Users/user/Downloads/insta_meta_test2/40018615_681232688905528_3207780218613792768_n.jpg.part' -> '/Users/user/Downloads/insta_meta_test2/40018615_681232688905528_3207780218613792768_n.jpg'
2019-03-24 23:48:41,498 - instagram_scraper.app - DEBUG - Exception in worker thread
Traceback (most recent call last):
  File "/usr/local/lib/python3.7/site-packages/instagram_scraper/app.py", line 385, in worker_wrapper
    return fn(*args, **kwargs)
  File "/usr/local/lib/python3.7/site-packages/instagram_scraper/app.py", line 956, in download
    os.rename(part_file, file_path)
FileNotFoundError: [Errno 2] No such file or directory: '/Users/user/Downloads/insta_meta_test2/33721412_172524563419859_3826263562301472768_n.jpg.part' -> '/Users/user/Downloads/insta_meta_test2/33721412_172524563419859_3826263562301472768_n.jpg'
2019-03-24 23:48:41,499 - instagram_scraper.app - WARNING - Media for 2000일 at ['https://scontent-hkg3-2.cdninstagram.com/vp/13702a2b6798db8da071d00da9b9f30d/5D10AAEC/t51.2885-15/e35/33721412_172524563419859_3826263562301472768_n.jpg?_nc_ht=scontent-hkg3-2.cdninstagram.com', 'https://scontent-hkg3-2.cdninstagram.com/vp/d61cb09aab21517eba0f1d5c8fa2a87b/5D1455F6/t51.2885-15/e35/34778883_394542007697130_2462862005623586816_n.jpg?_nc_ht=scontent-hkg3-2.cdninstagram.com', 'https://scontent-hkg3-2.cdninstagram.com/vp/497d31d8a3c66e4fc7d1057327b597f4/5D4CF732/t51.2885-15/e35/33559625_172429416757803_7381120259903717376_n.jpg?_nc_ht=scontent-hkg3-2.cdninstagram.com', 'https://scontent-hkg3-2.cdninstagram.com/vp/1b47325519077b0f1879ad178fa3f134/5D2F5928/t51.2885-15/e35/33879373_777281615814889_4374027821329154048_n.jpg?_nc_ht=scontent-hkg3-2.cdninstagram.com', 'https://scontent-hkg3-2.cdninstagram.com/vp/4787fcdbbddf3ecb9f19d0b5cac9a990/5D1A50F5/t51.2885-15/e35/34095351_239694083278754_794280263533199360_n.jpg?_nc_ht=scontent-hkg3-2.cdninstagram.com'] generated an exception: [Errno 2] No such file or directory: '/Users/user/Downloads/insta_meta_test2/33721412_172524563419859_3826263562301472768_n.jpg.part' -> '/Users/user/Downloads/insta_meta_test2/33721412_172524563419859_3826263562301472768_n.jpg'
